Workbook

Sheet задание
A1: № | B1: Условия акции - все задания выполнить с использованием формул, для каждого критерия создать отдельный столбец в котором указать, удовлетворяет ли строка отчета проверяемому критерию, остальные пункты графики и сводные таблицы делать на отдельных листах
A2: 1 | B2: дата отправки смс должна была быть в период 01.10 по 14.10 | C2: лист "выгрузка -- копия (2)"
A3: 3 | B3: у комплекта обязательно должна быть регистрация (дата регистрации) | C3: лист "выгрузка -- копия (2)"
A4: 4 | B4: дилер должен быть в списке дилеров (номер ЛС дилера должен быть со списка на листе "дилеры участники") | C4: лист "выгрузка -- копия (2)"
A5: 5 | B5: тарифный план должен быть в списке тарифных планов (лист "ставки тарифы") | C5: лист "выгрузка -- копия (2)"
A6: 6 | B6: канал дилера, чей комплект отправляется, должен быть среди каналов (стоять згачение 1), в которых отправленный тп бонусируется (см. лист ставки тарифы) | C6: лист "выгрузка -- копия (2)"
A7: 7 | B7: проверить отправленные номера комплектов на задвоения, если один и тот же номер отправлен несколько раз, то исключаются все комплекты кроме того, у которого дата отправки смс была ближе к дате активации (как до, так и после) | C7: на листе "Задание 7". Методика: 1) Создаём столбец с модулем разности даты активации и даты отправки смс. 2) Сортируем этот столбец по убыванию. 3) Сортируем столбец с номером комплекта по возрастанию. При этом повторяющиеся значения находятся рядом, при этом таблица всё ещё отсортирована по убыванию модуля разности. 4) Удаляем дубликаты по столбцу с номером комплекта, и из-за применённых сортировок остаются строки и наименьшим модулем разности.
A8: 8 | B8: произвести расчет вознаграждения для каждого отправленного смс с учетом суммы стартового баланса и дополнительного платежа (см. таблицу ставки и тарифы), смс должны удовлетварять всем предыдущим условиям | C8: лист "выгрузка -- копия (2)"
A9: 9 | B9: построить сводную таблицу в которой было бы видно, какому участнику (по его номеру) начисляется какое суммарное вознаграждение (упорядочить от наибольшего вознаграждения к меньшему) | C9: лист "Задание 9"
A10: 10 | B10: сгруппировать Тарифный планы по группам (Smart, Ultra, Супер МТС) | C10: лист "выгрузка -- копия (2)", столбец 10 -- группа тарифа
A11: 11 | B11: проанализировать смс, котрые не прошли по указанным критериям, сделать предположение, какой критерий(условие) можно добавить/отменить/изменить, чтобы больше комплектов попадали под бонусирование. | C11: Больше всего "срезается" из-за малого количества дилеров-участников, можно подключить больше дилеров к программе
A12: 12 | B12: вывести диаграмму из которой видно, какую долю среди уникальных блокированных абонентов занимает регион среди всех уникальных блокированных абонентов | C12: лист "Задание 12"
A13: 13 | B13: по блокированным определить в какой месяц от даты активации произошла блокировка | C13: лист "Задание 13". Надеюсь, правильно понял формулировку

Sheet ставки тарифы
C1: пороговые значения: | D1: 100 | E1: 200 | F1: 300
A2: Название ТП комплекта | B2: Локальный | C2: Непрофильный | D2: 0 | E2: 2 | F2: 3
A3: Smart (МАСС) (SCP) | B3: 1 | C3: 1 | D3: 0 | E3: 0 | F3: 120
A4: Smart 052013 (МАСС) (SCP) | B4: 1 | C4: 1 | D4: 0 | E4: 0 | F4: 120
A5: Smart 102014 (МАСС) (SCP) | B5: 1 | C5: 1 | D5: 0 | E5: 0 | F5: 120
A6: Smart mini (МАСС) (SCP) | B6: 1 | C6: 1 | D6: 70 | E6: 110 | F6: 110
A7: Smart mini 102014 (МАСС) (SCP) | B7: 1 | C7: 1 | D7: 70 | E7: 110 | F7: 110
A8: Smart mini 112013 (МАСС) (SCP) | B8: 1 | C8: 1 | D8: 70 | E8: 110 | F8: 110
A9: Smart Nonstop (МАСС) (SCP) | B9: 1 | C9: 1 | D9: 0 | E9: 0 | F9: 200
A10: Smart Top (МАСС) (SCP) | B10: 1 | C10: 1 | D10: 0 | E10: 0 | F10: 200
A11: Smart+ (МАСС) (SCP) | B11: 1 | C11: 1 | D11: 0 | E11: 0 | F11: 200
A12: Smart+ 102014 (МАСС) (SCP) | B12: 1 | C12: 1 | D12: 0 | E12: 0 | F12: 200
A13: Smart+ на год (МАСС) (SCP) | B13: 1 | C13: 1 | D13: 0 | E13: 0 | F13: 200
A14: Ultra (КОРП) (SS) | B14: 1 | C14: 1 | D14: 0 | E14: 0 | F14: 220
... A19: МТС Коннект-4 (МАСС) (SCP) | B19: 1 | C19: 1 | D19: 0 | E19: 100 | F19: 170
A20: Супер МТС (МАСС) (SCP) | C20: 1 | D20: 70 | E20: 70 | F20: 70
A21: Супер МТС 042014 (МАСС) (SCP) | C21: 1 | D21: 70 | E21: 70 | F21: 70
A22: Супер МТС 0513 (МАСС) (SCP) | C22: 1 | D22: 70 | E22: 70 | F22: 70
A23: Супер МТС 082013 (МАСС) (SCP) | C23: 1 | D23: 70 | E23: 70 | F23: 70
A24: Супер МТС 092014 (МАСС) (SCP) | C24: 1 | D24: 70 | E24: 70 | F24: 70
A25: Супер МТС 2012 (МАСС) (SCP) | C25: 1 | D25: 70 | E25: 70 | F25: 70
A26: Супер МТС 2013 (МАСС) (SCP) | C26: 1 | D26: 70 | E26: 70 | F26: 70
A27: Супер МТС. Область (МАСС) (SCP) | C27: 1 | D27: 70 | E27: 70 | F27: 70
A28: Супер МТС. Область 072014 (МАСС) (SCP) | C28: 1 | D28: 70 | E28: 70 | F28: 70
A29: Супер МТС_2011 (МАСС) (SCP) | C29: 1 | D29: 70 | E29: 70 | F29: 70

Sheet дилеры участники
A1: Дилеры участники
A2: 79956
A3: 64616
A4: 57078
A5: 66498

Sheet выгрузка 
A1: Дата отправки смс | B1: Номер отправителя | C1: Номер комплекта | D1: Дата активации | E1: Дата регистрации | F1: ЛС дилера | G1: Канал продажи | H1: ТП комплекта текущий | I1: ТП комплекта текущий2 | J1: Первоначальный баланс проданного комплекта | K1: Размер дополнительного платежа | L1: Сумма дополнительного платежа и стартового баланса | M1: статус комплекта | N1: дата блокировки
A2: 41583.542 | B2: 910467 | C2: 8500837 | D2: 41583.542 | E2: 41593.845 | F2: 79956 | G2: Непрофильный | H2: Тверь - Smart mini (МАСС) (SCP) | I2: Тверь - Smart mini (МАСС) (SCP) | J2: 30 | K2: 200 | L2: 230 | M2: Блокирован | N2: 41971
A3: 41558.712 | B3: 916012 | C3: 8511801 | D3: 41558.712 | F3: 73902 | G3: Непрофильный | H3: Тверь - Супер МТС (МАСС) (SCP) | I3: Тверь - Супер МТС (МАСС) (SCP) | J3: 30 | K3: 195 | L3: 225 | M3: Блокирован | N3: 41812
A4: 41555.831 | B4: 916692 | C4: 8550792 | D4: 41555.831 | F4: 73902 | G4: Непрофильный | H4: Тверь - Супер МТС (МАСС) (SCP) | I4: Тверь - Супер МТС (МАСС) (SCP) | J4: 30 | K4: 0 | L4: 30 | M4: Блокирован | N4: 41692
A5: 41557.684 | B5: 910441 | C5: 8514402 | D5: 41557.685 | F5: 73902 | G5: Непрофильный | H5: Тверь - МТС Коннект-4 (МАСС) (SCP) | I5: Тверь - МТС Коннект-4 (МАСС) (SCP) | J5: 949 | K5: 90.01 | L5: 1039.01 | M5: Блокирован | N5: 41803
A6: 41552.713 | B6: 919995 | C6: 1753744 | D6: 41552.712 | E6: 41552.716 | F6: 64626 | G6: Непрофильный | H6: Тверь - Smart mini (МАСС) (SCP) | I6: Тверь - Smart mini (МАСС) (SCP) | J6: 220 | K6: 0 | L6: 220 | M6: Активен
A7: 41560.465 | B7: 916496 | C7: 1755631 | D7: 41560.465 | F7: 64626 | G7: Непрофильный | H7: Тверь - МТС Коннект-4 (МАСС) (SCP) | I7: Тверь - МТС Коннект-4 (МАСС) (SCP) | J7: 30 | K7: 378 | L7: 408 | M7: Блокирован | N7: 41649
A8: 41559.574 | B8: 916496 | C8: 8503066 | D8: 41559.573 | E8: 41560.836 | F8: 64626 | G8: Непрофильный | H8: Тверь - МТС Коннект-4 (МАСС) (SCP) | I8: Тверь - МТС Коннект-4 (МАСС) (SCP) | J8: 30 | K8: 283.5 | L8: 313.5 | M8: Блокирован | N8: 41874
A9: 41561.285 | B9: 963978 | C9: 8520327 | D9: 41561.286 | F9: 64626 | G9: Непрофильный | H9: Тверь - Smart mini (МАСС) (SCP) | I9: Тверь - Smart mini (МАСС) (SCP) | J9: 30 | K9: 250 | L9: 280 | M9: Блокирован | N9: 41794
A10: 41560.411 | B10: 916496 | C10: 8520383 | D10: 41560.411 | F10: 64626 | G10: Непрофильный | H10: Тверь - МТС Коннект-4 (МАСС) (SCP) | I10: Тверь - МТС Коннект-4 (МАСС) (SCP) | J10: 1749 | K10: 0 | L10: 1749 | M10: Блокирован | N10: 41776
A11: 41554.326 | B11: 916496 | C11: 8503724 | D11: 41554.325 | E11: 41555.868 | F11: 64626 | G11: Непрофильный | H11: Тверь - МТС Коннект-4 (МАСС) (SCP) | I11: Тверь - МТС Коннект-4 (МАСС) (SCP) | J11: 30 | K11: 191 | L11: 221 | M11: Блокирован | N11: 41919
A12: 41560.824 | B12: 910467 | C12: 8500835 | D12: 41560.825 | F12: 79956 | G12: Непрофильный | H12: Тверь - Smart mini (МАСС) (SCP) | I12: Тверь - Smart mini (МАСС) (SCP) | J12: 30 | K12: 200 | L12: 230 | M12: Блокирован | N12: 41963
A13: 41551.599 | B13: 910450 | C13: 1996282 | D13: 41551.6 | F13: 64616 | G13: Непрофильный | H13: Тверь - Супер МТС (МАСС) (SCP) | I13: Тверь - Супер МТС (МАСС) (SCP) | J13: 30 | K13: 200 | L13: 230 | M13: Блокирован | N13: 41725
A14: 41561.664 | B14: 916566 | C14: 8527611 | D14: 41561.665 | F14: 64616 | G14: Непрофильный | H14: Тверь - Smart mini (МАСС) (SCP) | I14: Тверь - Smart mini (МАСС) (SCP) | J14: 30 | K14: 230 | L14: 260 | M14: Активен
A15: 41560.633 | B15: 910466 | C15: 8503673 | D15: 41560.634 | F15: 79956 | G15: Непрофильный | H15: Тверь - Smart mini (МАСС) (SCP) | I15: Тверь - Smart mini (МАСС) (SCP) | J15: 220 | K15: 0 | L15: 220 | M15: Блокирован | N15: 41844
A16: 41551.535 | B16: 910475 | C16: 8555316 | D16: 41551.534 | E16: 41556.434 | F16: 64626 | G16: Непрофильный | H16: Тверь - Smart mini (МАСС) (SCP) | I16: Тверь - Smart mini (МАСС) (SCP) | J16: 220 | K16: 0 | L16: 220 | M16: Блокирован | N16: 41969
A17: 41559.503 | B17: 915327 | C17: 1996837 | D17: 41559.505 | F17: 73902 | G17: Непрофильный | H17: Тверь - Супер МТС (МАСС) (SCP) | I17: Тверь - Супер МТС (МАСС) (SCP) | J17: 30 | K17: 1235 | L17: 1265 | M17: Блокирован | N17: 41890
A18: 41557.755 | B18: 917505 | C18: 1753781 | D18: 41557.754 | E18: 41558.78 | F18: 64626 | G18: Непрофильный | H18: Тверь - Smart mini (МАСС) (SCP) | I18: Тверь - Smart mini (МАСС) (SCP) | J18: 220 | K18: 0 | L18: 220 | M18: Активен
A19: 41555.665 | B19: 916692 | C19: 1753350 | D19: 41555.663 | F19: 73902 | G19: Непрофильный | H19: Тверь - Smart (МАСС) (SCP) | I19: Тверь - Smart (МАСС) (SCP) | J19: 30 | K19: 485 | L19: 515 | M19: Активен
A20: 41550.568 | B20: 916496 | C20: 8514427 | D20: 41550.567 | E20: 41560.808 | F20: 64626 | G20: Непрофильный | H20: Тверь - МТС Коннект-4 (МАСС) (SCP) | I20: Тверь - МТС Коннект-4 (МАСС) (SCP) | J20: 949 | K20: 0 | L20: 949 | M20: Блокирован | N20: 41815
A21: 41558.709 | B21: 910475 | C21: 8555317 | D21: 41558.707 | E21: 41560.99 | F21: 64626 | G21: Непрофильный | H21: Тверь - Smart mini (МАСС) (SCP) | I21: Тверь - Smart mini (МАСС) (SCP) | J21: 220 | K21: 0 | L21: 220 | M21: Блокирован | N21: 41955
A22: 41556.744 | B22: 916322 | C22: 1753092 | D22: 41556.746 | F22: 79956 | G22: Непрофильный | H22: Тверь - Smart mini (МАСС) (SCP) | I22: Тверь - Smart mini (МАСС) (SCP) | J22: 220 | K22: 0 | L22: 220 | M22: Активен
A23: 41556.441 | B23: 916496 | C23: 8503715 | D23: 41556.44 | E23: 41560.843 | F23: 64626 | G23: Непрофильный | H23: Тверь - МТС Коннект-4 (МАСС) (SCP) | I23: Тверь - МТС Коннект-4 (МАСС) (SCP) | J23: 30 | K23: 425.25 | L23: 455.25 | M23: Блокирован | N23: 41931
A24: 41551.605 | B24: 910441 | C24: 8561014 | D24: 41551.604 | E24: 41556.66 | F24: 73902 | G24: Непрофильный | H24: Тверь - МТС Коннект-4 (МАСС) (SCP) | I24: Тверь - МТС Коннект-4 (МАСС) (SCP) | J24: 30 | K24: 700 | L24: 730 | M24: Блокирован | N24: 41739
A25: 41553.706 | B25: 910487 | C25: 8563780 | D25: 41553.708 | F25: 73902 | G25: Непрофильный | H25: Тверь - Smart (МАСС) (SCP) | I25: Тверь - Smart (МАСС) (SCP) | J25: 470 | K25: 100 | L25: 570 | M25: Блокирован | N25: 41923
A26: 41558.766 | B26: 917505 | C26: 8524888 | D26: 41558.763 | E26: 41558.773 | F26: 64626 | G26: Непрофильный | H26: Тверь - МТС Коннект-4 (МАСС) (SCP) | I26: Тверь - МТС Коннект-4 (МАСС) (SCP) | J26: 401 | K26: 0 | L26: 401 | M26: Активен
A27: 41550.73 | B27: 916191 | C27: 8554807 | D27: 41550.732 | F27: 64616 | G27: Непрофильный | H27: Тверь - Smart (МАСС) (SCP) | I27: Тверь - Smart (МАСС) (SCP) | J27: 30 | K27: 700 | L27: 730 | M27: Блокирован | N27: 41718
A28: 41560.546 | B28: 919100 | C28: 8562412 | D28: 41560.544 | F28: 79956 | G28: Непрофильный | H28: Тверь - Супер МТС (МАСС) (SCP) | I28: Тверь - Супер МТС (МАСС) (SCP) | J28: 30 | K28: 188 | L28: 218 | M28: Блокирован | N28: 41783
A29: 41555.665 | B29: 916692 | C29: 1753359 | D29: 41555.663 | F29: 73902 | G29: Непрофильный | H29: Тверь - Smart (МАСС) (SCP) | I29: Тверь - Smart (МАСС) (SCP) | J29: 30 | K29: 485 | L29: 515 | M29: Активен
A30: 41554.443 | B30: 916425 | C30: 1999892 | D30: 41554.44 | F30: 79956 | G30: Непрофильный | H30: Тверь - Smart mini (МАСС) (SCP) | I30: Тверь - Smart mini (МАСС) (SCP) | J30: 220 | K30: 195.2 | L30: 415.2 | M30: Блокирован | N30: 42001
A31: 41548.566 | B31: 916510 | C31: 8502926 | D31: 41548.564 | E31: 41554.672 | F31: 73902 | G31: Непрофильный | H31: Тверь - Супер МТС. Область (МАСС) (SCP) | I31: Тверь - Супер МТС. Область (МАСС) (SCP) | J31: 30 | K31: 0 | L31: 30 | M31: Блокирован | N31: 41780
A32: 41548.7 | B32: 915323 | C32: 8503672 | D32: 41548.698 | E32: 41556.5 | F32: 64626 | G32: Непрофильный | H32: Тверь - Smart mini (МАСС) (SCP) | I32: Тверь - Smart mini (МАСС) (SCP) | J32: 20 | K32: 640 | L32: 660 | M32: Блокирован | N32: 41645
A33: 41556.465 | B33: 910459 | C33: 1755511 | D33: 41556.462 | E33: 41560.944 | F33: 64626 | G33: Непрофильный | H33: Тверь - Супер МТС (МАСС) (SCP) | I33: Тверь - Супер МТС (МАСС) (SCP) | J33: 30 | K33: 800 | L33: 830 | M33: Блокирован | N33: 41734
A34: 41551.561 | B34: 910475 | C34: 8555316 | D34: 41551.558 | E34: 41556.434 | F34: 64626 | G34: Непрофильный | H34: Тверь - Smart mini (МАСС) (SCP) | I34: Тверь - Smart mini (МАСС) (SCP) | J34: 220 | K34: 0 | L34: 220 | M34: Блокирован | N34: 41969
A35: 41561.735 | B35: 916542 | C35: 8500887 | D35: 41561.738 | F35: 79956 | G35: Непрофильный | H35: Тверь - Smart mini (МАСС) (SCP) | I35: Тверь - Smart mini (МАСС) (SCP) | J35: 30 | K35: 561.12 | L35: 591.12 | M35: Блокирован | N35: 41951
A36: 41554.609 | B36: 985351 | C36: 8500120 | D36: 41554.612 | E36: 41556.419 | F36: 79956 | G36: Непрофильный | H36: Тверь - Smart (МАСС) (SCP) | I36: Тверь - Smart (МАСС) (SCP) | J36: 470 | K36: 0 | L36: 470 | M36: Блокирован | N36: 41763
A37: 41553.702 | B37: 917505 | C37: 1753770 | D37: 41553.699 | E37: 41553.9 | F37: 64626 | G37: Непрофильный | H37: Тверь - Smart mini (МАСС) (SCP) | I37: Тверь - Smart mini (МАСС) (SCP) | J37: 220 | K37: 0 | L37: 220 | M37: Активен
A38: 41583.834 | B38: 910486 | C38: 8527896 | D38: 41583.83 | E38: 41585.695 | F38: 79956 | G38: Непрофильный | H38: Тверь - МТС Коннект-4 (МАСС) (SCP) | I38: Тверь - МТС Коннект-4 (МАСС) (SCP) | J38: 30 | K38: 752 | L38: 782 | M38: Активен
A39: 41559.818 | B39: 910488 | C39: 1750460 | D39: 41559.821 | E39: 41560.404 | F39: 64626 | G39: Непрофильный | H39: Тверь - Smart mini (МАСС) (SCP) | I39: Тверь - Smart mini (МАСС) (SCP) | J39: 220 | K39: 0 | L39: 220 | M39: Активен
A40: 41561.934 | B40: 915000 | C40: 8562212 | D40: 41561.93 | F40: 79956 | G40: Непрофильный | H40: Тверь - Smart mini (МАСС) (SCP) | I40: Тверь - Smart mini (МАСС) (SCP) | J40: 270 | K40: 0 | L40: 270 | M40: Блокирован | N40: 41822
...

Sheet выгрузка -- копия (2)
A1: Дата отправки смс | B1: Номер отправителя | C1: Номер комплекта | D1: Дата активации | E1: Месяц активации | F1: Дата регистрации | G1: ЛС дилера | H1: Канал продажи | I1: ТП комплекта текущий.1 | J1: ТП комплекта текущий.2 | K1: Первоначальный баланс проданного комплекта | L1: Размер дополнительного платежа | M1: Сумма дополнительного платежа и стартового баланса | N1: статус комплекта | O1: Дата блокировки | P1: ТП комплекта текущий без города (столбец создан с помощью Power Query) | Q1: Критерий 1 -- от 1 до 14 октября | R1: Критерий 3 -- дата регистрации | S1: Критерий 4 -- дилеры-участники | T1: Критерий 5 -- ТП из списка | U1: Критерий 6 -- бонус в канале | V1: 8 --Вознаграждение | W1: 10 --Группа тарифа | X1: 13 --Месяц блокировки от месяца подключения | Y1: Блокировка
A2: 41593.654 | B2: 915323 | C2: 1751529 | D2: 41593.716 | E2: =IF(выгрузка__22[[#This Row],[Дата активации]]<>"",MONTH(выгрузка__22[[#This Row],[Дата активации]]),0) -> 11 | G2: 64628 | H2: Непрофильный | I2: Тверь | J2: - Супер МТС (МАСС) (SCP) | K2: 30 | L2: 0 | M2: 30 | N2: Активен | P2: Супер МТС (МАСС) (SCP) | Q2: =IF(AND(DAY(выгрузка__22[[#This Row],[Дата отправки смс]])>=1,DAY(выгрузка__22[[#This Row],[Дата отправки смс]])<=14,MONTH(выгрузка__22[[#This Row],[Дата отправки смс]])=10),1,0) -> 0 | R2: =IF(выгрузка__22[[#This Row],[Дата регистрации]]="",0,1) -> 0 | S2: =IF(ISNA(VLOOKUP(выгрузка__22[[#This Row],[ЛС дилера]],'дилеры участники'!A:A,1,0)),0,1) -> 0 | T2: =IF(ISNA(VLOOKUP(выгрузка__22[[#This Row],[ТП комплекта текущий без города (столбец создан с помощью Power Query)]],Таблица3[Название ТП комплекта],1,0)),0,1) -> 1 | U2: =IF(ISNA(IF(выгрузка__22[[#This Row],[Канал продажи]]="Непрофильный",VLOOKUP(выгрузка__22[[#This Row],[ТП комплекта текущий без города (столбец создан с помощью Power Query)]],Таблица3[[Название ТП комплекта]:[Непрофильный]],3,0),VLOOKUP(выгрузка__22[[#This Row],[ТП комплекта текущий без города (столбец создан с помощью Power Query)]],Таблица3[[Название ТП комплекта]:[Непрофильный]],2,0)))=FALSE,1,0) -> 1 | V2: =IF(T2=1,IF(выгрузка__22[[#This Row],[Сумма дополнительного платежа и стартового баланса]]>300,VLOOKUP(выгрузка__22[[#This Row],[ТП комплекта текущий без города (столбец создан с помощью Power Query)]],Таблица3[],6,0),IF(выгрузка__22[[#This Row],[Сумма дополнительного платежа и стартового баланса]]>200,VLOOKUP(выгрузка__22[[#This Row],[ТП комплекта текущий без города (столбец создан с помощью Power Query)]],Таблица3[],5,0),IF(выгрузка__22[[#This Row],[Сумма дополнительного платежа и стартового баланса]]>100,VLOOKUP(выгрузка__22[[#This Row],[ТП комплекта текущий без города (столбец создан с помощью Power Query)]],Таблица3[],4,0),0))),0) -> 0 | W2: Супер МТС | X2: =IF(выгрузка__22[[#This Row],[Дата активации]]<>0,IF(выгрузка__22[[#This Row],[Дата блокировки]]<>"",CEILING((выгрузка__22[[#This Row],[Дата блокировки]]-выгрузка__22[[#This Row],[Дата активации]])/30,1),0),0) -> 0 | Y2: =IF(выгрузка__22[[#This Row],[Дата блокировки]]<>"",1,0) -> 0
A3: 41593.714 | B3: 916207 | C3: 1751479 | D3: 41593.7 | E3: =IF(выгрузка__22[[#This Row],[Дата активации]]<>"",MONTH(выгрузка__22[[#This Row],[Дата активации]]),0) -> 11 | G3: 64626 | H3: Непрофильный | I3: Тверь | J3: - Супер МТС (МАСС) (SCP) | K3: 30 | L3: 0 | M3: 30 | N3: Активен | P3: Супер МТС (МАСС) (SCP) | Q3: =IF(AND(DAY(выгрузка__22[[#This Row],[Дата отправки смс]])>=1,DAY(выгрузка__22[[#This Row],[Дата отправки смс]])<=14,MONTH(выгрузка__22[[#This Row],[Дата отправки смс]])=10),1,0) -> 0 | R3: =IF(выгрузка__22[[#This Row],[Дата регистрации]]="",0,1) -> 0 | S3: =IF(ISNA(VLOOKUP(выгрузка__22[[#This Row],[ЛС дилера]],'дилеры участники'!A:A,1,0)),0,1) -> 0 | T3: =IF(ISNA(VLOOKUP(выгрузка__22[[#This Row],[ТП комплекта текущий без города (столбец создан с помощью Power Query)]],Таблица3[Название ТП комплекта],1,0)),0,1) -> 1 | U3: =IF(ISNA(IF(выгрузка__22[[#This Row],[Канал продажи]]="Непрофильный",VLOOKUP(выгрузка__22[[#This Row],[ТП комплекта текущий без города (столбец создан с помощью Power Query)]],Таблица3[[Название ТП комплекта]:[Непрофильный]],3,0),VLOOKUP(выгрузка__22[[#This Row],[ТП комплекта текущий без города (столбец создан с помощью Power Query)]],Таблица3[[Название ТП комплекта]:[Непрофильный]],2,0)))=FALSE,1,0) -> 1 | V3: =IF(T3=1,IF(выгрузка__22[[#This Row],[Сумма дополнительного платежа и стартового баланса]]>300,VLOOKUP(выгрузка__22[[#This Row],[ТП комплекта текущий без города (столбец создан с помощью Power Query)]],Таблица3[],6,0),IF(выгрузка__22[[#This Row],[Сумма дополнительного платежа и стартового баланса]]>200,VLOOKUP(выгрузка__22[[#This Row],[ТП комплекта текущий без города (столбец создан с помощью Power Query)]],Таблица3[],5,0),IF(выгрузка__22[[#This Row],[Сумма дополнительного платежа и стартового баланса]]>100,VLOOKUP(выгрузка__22[[#This Row],[ТП комплекта текущий без города (столбец создан с помощью Power Query)]],Таблица3[],4,0),0))),0) -> 0 | W3: Супер МТС | X3: =IF(выгрузка__22[[#This Row],[Дата активации]]<>0,IF(выгрузка__22[[#This Row],[Дата блокировки]]<>"",CEILING((выгрузка__22[[#This Row],[Дата блокировки]]-выгрузка__22[[#This Row],[Дата активации]])/30,1),0),0) -> 0 | Y3: =IF(выгрузка__22[[#This Row],[Дата блокировки]]<>"",1,0) -> 0
A4: 41593.669 | B4: 916510 | C4: 1698170 | D4: 41593.676 | E4: =IF(выгрузка__22[[#This Row],[Дата активации]]<>"",MONTH(выгрузка__22[[#This Row],[Дата активации]]),0) -> 11 | G4: 73902 | H4: Непрофильный | I4: Тверь | J4: - Супер МТС (МАСС) (SCP) | K4: 1 | L4: 88 | M4: 89 | N4: Активен | P4: Супер МТС (МАСС) (SCP) | Q4: =IF(AND(DAY(выгрузка__22[[#This Row],[Дата отправки смс]])>=1,DAY(выгрузка__22[[#This Row],[Дата отправки смс]])<=14,MONTH(выгрузка__22[[#This Row],[Дата отправки смс]])=10),1,0) -> 0 | R4: =IF(выгрузка__22[[#This Row],[Дата регистрации]]="",0,1) -> 0 | S4: =IF(ISNA(VLOOKUP(выгрузка__22[[#This Row],[ЛС дилера]],'дилеры участники'!A:A,1,0)),0,1) -> 0 | T4: =IF(ISNA(VLOOKUP(выгрузка__22[[#This Row],[ТП комплекта текущий без города (столбец создан с помощью Power Query)]],Таблица3[Название ТП комплекта],1,0)),0,1) -> 1 | U4: =IF(ISNA(IF(выгрузка__22[[#This Row],[Канал продажи]]="Непрофильный",VLOOKUP(выгрузка__22[[#This Row],[ТП комплекта текущий без города (столбец создан с помощью Power Query)]],Таблица3[[Название ТП комплекта]:[Непрофильный]],3,0),VLOOKUP(выгрузка__22[[#This Row],[ТП комплекта текущий без города (столбец создан с помощью Power Query)]],Таблица3[[Название ТП комплекта]:[Непрофильный]],2,0)))=FALSE,1,0) -> 1 | V4: =IF(T4=1,IF(выгрузка__22[[#This Row],[Сумма дополнительного платежа и стартового баланса]]>300,VLOOKUP(выгрузка__22[[#This Row],[ТП комплекта текущий без города (столбец создан с помощью Power Query)]],Таблица3[],6,0),IF(выгрузка__22[[#This Row],[Сумма дополнительного платежа и стартового баланса]]>200,VLOOKUP(выгрузка__22[[#This Row],[ТП комплекта текущий без города (столбец создан с помощью Power Query)]],Таблица3[],5,0),IF(выгрузка__22[[#This Row],[Сумма дополнительного платежа и стартового баланса]]>100,VLOOKUP(выгрузка__22[[#This Row],[ТП комплекта текущий без города (столбец создан с помощью Power Query)]],Таблица3[],4,0),0))),0) -> 0 | W4: Супер МТС | X4: =IF(выгрузка__22[[#This Row],[Дата активации]]<>0,IF(выгрузка__22[[#This Row],[Дата блокировки]]<>"",CEILING((выгрузка__22[[#This Row],[Дата блокировки]]-выгрузка__22[[#This Row],[Дата активации]])/30,1),0),0) -> 0 | Y4: =IF(выгрузка__22[[#This Row],[Дата блокировки]]<>"",1,0) -> 0
A5: 41593.534 | B5: 916726 | C5: 8545217 | D5: 41593.586 | E5: =IF(выгрузка__22[[#This Row],[Дата активации]]<>"",MONTH(выгрузка__22[[#This Row],[Дата активации]]),0) -> 11 | G5: 64626 | H5: Непрофильный | I5: Тверь | J5: - Smart mini (МАСС) (SCP) | K5: 30 | L5: 190 | M5: 220 | N5: Активен | P5: Smart mini (МАСС) (SCP) | Q5: =IF(AND(DAY(выгрузка__22[[#This Row],[Дата отправки смс]])>=1,DAY(выгрузка__22[[#This Row],[Дата отправки смс]])<=14,MONTH(выгрузка__22[[#This Row],[Дата отправки смс]])=10),1,0) -> 0 | R5: =IF(выгрузка__22[[#This Row],[Дата регистрации]]="",0,1) -> 0 | S5: =IF(ISNA(VLOOKUP(выгрузка__22[[#This Row],[ЛС дилера]],'дилеры участники'!A:A,1,0)),0,1) -> 0 | T5: =IF(ISNA(VLOOKUP(выгрузка__22[[#This Row],[ТП комплекта текущий без города (столбец создан с помощью Power Query)]],Таблица3[Название ТП комплекта],1,0)),0,1) -> 1 | U5: =IF(ISNA(IF(выгрузка__22[[#This Row],[Канал продажи]]="Непрофильный",VLOOKUP(выгрузка__22[[#This Row],[ТП комплекта текущий без города (столбец создан с помощью Power Query)]],Таблица3[[Название ТП комплекта]:[Непрофильный]],3,0),VLOOKUP(выгрузка__22[[#This Row],[ТП комплекта текущий без города (столбец создан с помощью Power Query)]],Таблица3[[Название ТП комплекта]:[Непрофильный]],2,0)))=FALSE,1,0) -> 1 | V5: =IF(T5=1,IF(выгрузка__22[[#This Row],[Сумма дополнительного платежа и стартового баланса]]>300,VLOOKUP(выгрузка__22[[#This Row],[ТП комплекта текущий без города (столбец создан с помощью Power Query)]],Таблица3[],6,0),IF(выгрузка__22[[#This Row],[Сумма дополнительного платежа и стартового баланса]]>200,VLOOKUP(выгрузка__22[[#This Row],[ТП комплекта текущий без города (столбец создан с помощью Power Query)]],Таблица3[],5,0),IF(выгрузка__22[[#This Row],[Сумма дополнительного платежа и стартового баланса]]>100,VLOOKUP(выгрузка__22[[#This Row],[ТП комплекта текущий без города (столбец создан с помощью Power Query)]],Таблица3[],4,0),0))),0) -> 110 | W5: Smart mini | X5: =IF(выгрузка__22[[#This Row],[Дата активации]]<>0,IF(выгрузка__22[[#This Row],[Дата блокировки]]<>"",CEILING((выгрузка__22[[#This Row],[Дата блокировки]]-выгрузка__22[[#This Row],[Дата активации]])/30,1),0),0) -> 0 | Y5: =IF(выгрузка__22[[#This Row],[Дата блокировки]]<>"",1,0) -> 0
A6: 41593.654 | B6: 910488 | C6: 1750456 | D6: 41592.85 | E6: =IF(выгрузка__22[[#This Row],[Дата активации]]<>"",MONTH(выгрузка__22[[#This Row],[Дата активации]]),0) -> 11 | F6: 41592.837 | G6: 64626 | H6: Непрофильный | I6: Тверь | J6: - Smart mini (МАСС) (SCP) | K6: 220 | L6: 0 | M6: 220 | N6: Активен | P6: Smart mini (МАСС) (SCP) | Q6: =IF(AND(DAY(выгрузка__22[[#This Row],[Дата отправки смс]])>=1,DAY(выгрузка__22[[#This Row],[Дата отправки смс]])<=14,MONTH(выгрузка__22[[#This Row],[Дата отправки смс]])=10),1,0) -> 0 | R6: =IF(выгрузка__22[[#This Row],[Дата регистрации]]="",0,1) -> 1 | S6: =IF(ISNA(VLOOKUP(выгрузка__22[[#This Row],[ЛС дилера]],'дилеры участники'!A:A,1,0)),0,1) -> 0 | T6: =IF(ISNA(VLOOKUP(выгрузка__22[[#This Row],[ТП комплекта текущий без города (столбец создан с помощью Power Query)]],Таблица3[Название ТП комплекта],1,0)),0,1) -> 1 | U6: =IF(ISNA(IF(выгрузка__22[[#This Row],[Канал продажи]]="Непрофильный",VLOOKUP(выгрузка__22[[#This Row],[ТП комплекта текущий без города (столбец создан с помощью Power Query)]],Таблица3[[Название ТП комплекта]:[Непрофильный]],3,0),VLOOKUP(выгрузка__22[[#This Row],[ТП комплекта текущий без города (столбец создан с помощью Power Query)]],Таблица3[[Название ТП комплекта]:[Непрофильный]],2,0)))=FALSE,1,0) -> 1 | V6: =IF(T6=1,IF(выгрузка__22[[#This Row],[Сумма дополнительного платежа и стартового баланса]]>300,VLOOKUP(выгрузка__22[[#This Row],[ТП комплекта текущий без города (столбец создан с помощью Power Query)]],Таблица3[],6,0),IF(выгрузка__22[[#This Row],[Сумма дополнительного платежа и стартового баланса]]>200,VLOOKUP(выгрузка__22[[#This Row],[ТП комплекта текущий без города (столбец создан с помощью Power Query)]],Таблица3[],5,0),IF(выгрузка__22[[#This Row],[Сумма дополнительного платежа и стартового баланса]]>100,VLOOKUP(выгрузка__22[[#This Row],[ТП комплекта текущий без города (столбец создан с помощью Power Query)]],Таблица3[],4,0),0))),0) -> 110 | W6: Smart mini | X6: =IF(выгрузка__22[[#This Row],[Дата активации]]<>0,IF(выгрузка__22[[#This Row],[Дата блокировки]]<>"",CEILING((выгрузка__22[[#This Row],[Дата блокировки]]-выгрузка__22[[#This Row],[Дата активации]])/30,1),0),0) -> 0 | Y6: =IF(выгрузка__22[[#This Row],[Дата блокировки]]<>"",1,0) -> 0
A7: 41593.497 | B7: 910489 | C7: 8525534 | D7: 41591.638 | E7: =IF(выгрузка__22[[#This Row],[Дата активации]]<>"",MONTH(выгрузка__22[[#This Row],[Дата активации]]),0) -> 11 | G7: 64616 | H7: Непрофильный | I7: Тверь | J7: - Твоя страна (МАСС) (SCP) | K7: 30 | L7: 0 | M7: 30 | N7: Активен | P7: Твоя страна (МАСС) (SCP) | Q7: =IF(AND(DAY(выгрузка__22[[#This Row],[Дата отправки смс]])>=1,DAY(выгрузка__22[[#This Row],[Дата отправки смс]])<=14,MONTH(выгрузка__22[[#This Row],[Дата отправки смс]])=10),1,0) -> 0 | R7: =IF(выгрузка__22[[#This Row],[Дата регистрации]]="",0,1) -> 0 | S7: =IF(ISNA(VLOOKUP(выгрузка__22[[#This Row],[ЛС дилера]],'дилеры участники'!A:A,1,0)),0,1) -> 1 | T7: =IF(ISNA(VLOOKUP(выгрузка__22[[#This Row],[ТП комплекта текущий без города (столбец создан с помощью Power Query)]],Таблица3[Название ТП комплекта],1,0)),0,1) -> 0 | U7: =IF(ISNA(IF(выгрузка__22[[#This Row],[Канал продажи]]="Непрофильный",VLOOKUP(выгрузка__22[[#This Row],[ТП комплекта текущий без города (столбец создан с помощью Power Query)]],Таблица3[[Название ТП комплекта]:[Непрофильный]],3,0),VLOOKUP(выгрузка__22[[#This Row],[ТП комплекта текущий без города (столбец создан с помощью Power Query)]],Таблица3[[Название ТП комплекта]:[Непрофильный]],2,0)))=FALSE,1,0) -> 0 | V7: =IF(T7=1,IF(выгрузка__22[[#This Row],[Сумма дополнительного платежа и стартового баланса]]>300,VLOOKUP(выгрузка__22[[#This Row],[ТП комплекта текущий без города (столбец создан с помощью Power Query)]],Таблица3[],6,0),IF(выгрузка__22[[#This Row],[Сумма дополнительного платежа и стартового баланса]]>200,VLOOKUP(выгрузка__22[[#This Row],[ТП комплекта текущий без города (столбец создан с помощью Power Query)]],Таблица3[],5,0),IF(выгрузка__22[[#This Row],[Сумма дополнительного платежа и стартового баланса]]>100,VLOOKUP(выгрузка__22[[#This Row],[ТП комплекта текущий без города (столбец создан с помощью Power Query)]],Таблица3[],4,0),0))),0) -> 0 | W7: Твоя страна | X7: =IF(выгрузка__22[[#This Row],[Дата активации]]<>0,IF(выгрузка__22[[#This Row],[Дата блокировки]]<>"",CEILING((выгрузка__22[[#This Row],[Дата блокировки]]-выгрузка__22[[#This Row],[Дата активации]])/30,1),0),0) -> 0 | Y7: =IF(выгрузка__22[[#This Row],[Дата блокировки]]<>"",1,0) -> 0
A8: 41593.939 | B8: 910470 | C8: 8544488 | D8: 41590.755 | E8: =IF(выгрузка__22[[#This Row],[Дата активации]]<>"",MONTH(выгрузка__22[[#This Row],[Дата активации]]),0) -> 11 | G8: 64628 | H8: Непрофильный | I8: Тверь | J8: - Smart mini (МАСС) (SCP) | K8: 30 | L8: 200 | M8: 230 | N8: Активен | P8: Smart mini (МАСС) (SCP) | Q8: =IF(AND(DAY(выгрузка__22[[#This Row],[Дата отправки смс]])>=1,DAY(выгрузка__22[[#This Row],[Дата отправки смс]])<=14,MONTH(выгрузка__22[[#This Row],[Дата отправки смс]])=10),1,0) -> 0 | R8: =IF(выгрузка__22[[#This Row],[Дата регистрации]]="",0,1) -> 0 | S8: =IF(ISNA(VLOOKUP(выгрузка__22[[#This Row],[ЛС дилера]],'дилеры участники'!A:A,1,0)),0,1) -> 0 | T8: =IF(ISNA(VLOOKUP(выгрузка__22[[#This Row],[ТП комплекта текущий без города (столбец создан с помощью Power Query)]],Таблица3[Название ТП комплекта],1,0)),0,1) -> 1 | U8: =IF(ISNA(IF(выгрузка__22[[#This Row],[Канал продажи]]="Непрофильный",VLOOKUP(выгрузка__22[[#This Row],[ТП комплекта текущий без города (столбец создан с помощью Power Query)]],Таблица3[[Название ТП комплекта]:[Непрофильный]],3,0),VLOOKUP(выгрузка__22[[#This Row],[ТП комплекта текущий без города (столбец создан с помощью Power Query)]],Таблица3[[Название ТП комплекта]:[Непрофильный]],2,0)))=FALSE,1,0) -> 1 | V8: =IF(T8=1,IF(выгрузка__22[[#This Row],[Сумма дополнительного платежа и стартового баланса]]>300,VLOOKUP(выгрузка__22[[#This Row],[ТП комплекта текущий без города (столбец создан с помощью Power Query)]],Таблица3[],6,0),IF(выгрузка__22[[#This Row],[Сумма дополнительного платежа и стартового баланса]]>200,VLOOKUP(выгрузка__22[[#This Row],[ТП комплекта текущий без города (столбец создан с помощью Power Query)]],Таблица3[],5,0),IF(выгрузка__22[[#This Row],[Сумма дополнительного платежа и стартового баланса]]>100,VLOOKUP(выгрузка__22[[#This Row],[ТП комплекта текущий без города (столбец создан с помощью Power Query)]],Таблица3[],4,0),0))),0) -> 110 | W8: Smart mini | X8: =IF(выгрузка__22[[#This Row],[Дата активации]]<>0,IF(выгрузка__22[[#This Row],[Дата блокировки]]<>"",CEILING((выгрузка__22[[#This Row],[Дата блокировки]]-выгрузка__22[[#This Row],[Дата активации]])/30,1),0),0) -> 0 | Y8: =IF(выгрузка__22[[#This Row],[Дата блокировки]]<>"",1,0) -> 0
A9: 41593.927 | B9: 916531 | C9: 8544557 | D9: 41590.713 | E9: =IF(выгрузка__22[[#This Row],[Дата активации]]<>"",MONTH(выгрузка__22[[#This Row],[Дата активации]]),0) -> 11 | G9: 64628 | H9: Непрофильный | I9: Тверь | J9: - Smart mini (МАСС) (SCP) | K9: 30 | L9: 200 | M9: 230 | N9: Активен | P9: Smart mini (МАСС) (SCP) | Q9: =IF(AND(DAY(выгрузка__22[[#This Row],[Дата отправки смс]])>=1,DAY(выгрузка__22[[#This Row],[Дата отправки смс]])<=14,MONTH(выгрузка__22[[#This Row],[Дата отправки смс]])=10),1,0) -> 0 | R9: =IF(выгрузка__22[[#This Row],[Дата регистрации]]="",0,1) -> 0 | S9: =IF(ISNA(VLOOKUP(выгрузка__22[[#This Row],[ЛС дилера]],'дилеры участники'!A:A,1,0)),0,1) -> 0 | T9: =IF(ISNA(VLOOKUP(выгрузка__22[[#This Row],[ТП комплекта текущий без города (столбец создан с помощью Power Query)]],Таблица3[Название ТП комплекта],1,0)),0,1) -> 1 | U9: =IF(ISNA(IF(выгрузка__22[[#This Row],[Канал продажи]]="Непрофильный",VLOOKUP(выгрузка__22[[#This Row],[ТП комплекта текущий без города (столбец создан с помощью Power Query)]],Таблица3[[Название ТП комплекта]:[Непрофильный]],3,0),VLOOKUP(выгрузка__22[[#This Row],[ТП комплекта текущий без города (столбец создан с помощью Power Query)]],Таблица3[[Название ТП комплекта]:[Непрофильный]],2,0)))=FALSE,1,0) -> 1 | V9: =IF(T9=1,IF(выгрузка__22[[#This Row],[Сумма дополнительного платежа и стартового баланса]]>300,VLOOKUP(выгрузка__22[[#This Row],[ТП комплекта текущий без города (столбец создан с помощью Power Query)]],Таблица3[],6,0),IF(выгрузка__22[[#This Row],[Сумма дополнительного платежа и стартового баланса]]>200,VLOOKUP(выгрузка__22[[#This Row],[ТП комплекта текущий без города (столбец создан с помощью Power Query)]],Таблица3[],5,0),IF(выгрузка__22[[#This Row],[Сумма дополнительного платежа и стартового баланса]]>100,VLOOKUP(выгрузка__22[[#This Row],[ТП комплекта текущий без города (столбец создан с помощью Power Query)]],Таблица3[],4,0),0))),0) -> 110 | W9: Smart mini | X9: =IF(выгрузка__22[[#This Row],[Дата активации]]<>0,IF(выгрузка__22[[#This Row],[Дата блокировки]]<>"",CEILING((выгрузка__22[[#This Row],[Дата блокировки]]-выгрузка__22[[#This Row],[Дата активации]])/30,1),0),0) -> 0 | Y9: =IF(выгрузка__22[[#This Row],[Дата блокировки]]<>"",1,0) -> 0
A10: 41593.591 | B10: 916512 | C10: 1698576 | D10: 41589.987 | E10: =IF(выгрузка__22[[#This Row],[Дата активации]]<>"",MONTH(выгрузка__22[[#This Row],[Дата активации]]),0) -> 11 | F10: 41591.94 | G10: 64626 | H10: Непрофильный | I10: Тверь | J10: - Супер МТС. Область (МАСС) (SCP) | K10: 30 | L10: 0 | M10: 30 | N10: Активен | P10: Супер МТС. Область (МАСС) (SCP) | Q10: =IF(AND(DAY(выгрузка__22[[#This Row],[Дата отправки смс]])>=1,DAY(выгрузка__22[[#This Row],[Дата отправки смс]])<=14,MONTH(выгрузка__22[[#This Row],[Дата отправки смс]])=10),1,0) -> 0 | R10: =IF(выгрузка__22[[#This Row],[Дата регистрации]]="",0,1) -> 1 | S10: =IF(ISNA(VLOOKUP(выгрузка__22[[#This Row],[ЛС дилера]],'дилеры участники'!A:A,1,0)),0,1) -> 0 | T10: =IF(ISNA(VLOOKUP(выгрузка__22[[#This Row],[ТП комплекта текущий без города (столбец создан с помощью Power Query)]],Таблица3[Название ТП комплекта],1,0)),0,1) -> 1 | U10: =IF(ISNA(IF(выгрузка__22[[#This Row],[Канал продажи]]="Непрофильный",VLOOKUP(выгрузка__22[[#This Row],[ТП комплекта текущий без города (столбец создан с помощью Power Query)]],Таблица3[[Название ТП комплекта]:[Непрофильный]],3,0),VLOOKUP(выгрузка__22[[#This Row],[ТП комплекта текущий без города (столбец создан с помощью Power Query)]],Таблица3[[Название ТП комплекта]:[Непрофильный]],2,0)))=FALSE,1,0) -> 1 | V10: =IF(T10=1,IF(выгрузка__22[[#This Row],[Сумма дополнительного платежа и стартового баланса]]>300,VLOOKUP(выгрузка__22[[#This Row],[ТП комплекта текущий без города (столбец создан с помощью Power Query)]],Таблица3[],6,0),IF(выгрузка__22[[#This Row],[Сумма дополнительного платежа и стартового баланса]]>200,VLOOKUP(выгрузка__22[[#This Row],[ТП комплекта текущий без города (столбец создан с помощью Power Query)]],Таблица3[],5,0),IF(выгрузка__22[[#This Row],[Сумма дополнительного платежа и стартового баланса]]>100,VLOOKUP(выгрузка__22[[#This Row],[ТП комплекта текущий без города (столбец создан с помощью Power Query)]],Таблица3[],4,0),0))),0) -> 0 | W10: Супер МТС. Область | X10: =IF(выгрузка__22[[#This Row],[Дата активации]]<>0,IF(выгрузка__22[[#This Row],[Дата блокировки]]<>"",CEILING((выгрузка__22[[#This Row],[Дата блокировки]]-выгрузка__22[[#This Row],[Дата активации]])/30,1),0),0) -> 0 | Y10: =IF(выгрузка__22[[#This Row],[Дата блокировки]]<>"",1,0) -> 0
A11: 41593.502 | B11: 985210 | C11: 1754810 | D11: 41589.829 | E11: =IF(выгрузка__22[[#This Row],[Дата активации]]<>"",MONTH(выгрузка__22[[#This Row],[Дата активации]]),0) -> 11 | F11: 41591.846 | G11: 64626 | H11: Непрофильный | I11: Тверь | J11: - МТС Коннект-4 (МАСС) (SCP) | K11: 30 | L11: 0 | M11: 30 | N11: Активен | P11: МТС Коннект-4 (МАСС) (SCP) | Q11: =IF(AND(DAY(выгрузка__22[[#This Row],[Дата отправки смс]])>=1,DAY(выгрузка__22[[#This Row],[Дата отправки смс]])<=14,MONTH(выгрузка__22[[#This Row],[Дата отправки смс]])=10),1,0) -> 0 | R11: =IF(выгрузка__22[[#This Row],[Дата регистрации]]="",0,1) -> 1 | S11: =IF(ISNA(VLOOKUP(выгрузка__22[[#This Row],[ЛС дилера]],'дилеры участники'!A:A,1,0)),0,1) -> 0 | T11: =IF(ISNA(VLOOKUP(выгрузка__22[[#This Row],[ТП комплекта текущий без города (столбец создан с помощью Power Query)]],Таблица3[Название ТП комплекта],1,0)),0,1) -> 1 | U11: =IF(ISNA(IF(выгрузка__22[[#This Row],[Канал продажи]]="Непрофильный",VLOOKUP(выгрузка__22[[#This Row],[ТП комплекта текущий без города (столбец создан с помощью Power Query)]],Таблица3[[Название ТП комплекта]:[Непрофильный]],3,0),VLOOKUP(выгрузка__22[[#This Row],[ТП комплекта текущий без города (столбец создан с помощью Power Query)]],Таблица3[[Название ТП комплекта]:[Непрофильный]],2,0)))=FALSE,1,0) -> 1 | V11: =IF(T11=1,IF(выгрузка__22[[#This Row],[Сумма дополнительного платежа и стартового баланса]]>300,VLOOKUP(выгрузка__22[[#This Row],[ТП комплекта текущий без города (столбец создан с помощью Power Query)]],Таблица3[],6,0),IF(выгрузка__22[[#This Row],[Сумма дополнительного платежа и стартового баланса]]>200,VLOOKUP(выгрузка__22[[#This Row],[ТП комплекта текущий без города (столбец создан с помощью Power Query)]],Таблица3[],5,0),IF(выгрузка__22[[#This Row],[Сумма дополнительного платежа и стартового баланса]]>100,VLOOKUP(выгрузка__22[[#This Row],[ТП комплекта текущий без города (столбец создан с помощью Power Query)]],Таблица3[],4,0),0))),0) -> 0 | W11: МТС Коннект-4 | X11: =IF(выгрузка__22[[#This Row],[Дата активации]]<>0,IF(выгрузка__22[[#This Row],[Дата блокировки]]<>"",CEILING((выгрузка__22[[#This Row],[Дата блокировки]]-выгрузка__22[[#This Row],[Дата активации]])/30,1),0),0) -> 0 | Y11: =IF(выгрузка__22[[#This Row],[Дата блокировки]]<>"",1,0) -> 0
A12: 41593.588 | B12: 916512 | C12: 1697829 | D12: 41589.806 | E12: =IF(выгрузка__22[[#This Row],[Дата активации]]<>"",MONTH(выгрузка__22[[#This Row],[Дата активации]]),0) -> 11 | F12: 41591.855 | G12: 64626 | H12: Непрофильный | I12: Тверь | J12: - Супер МТС. Область (МАСС) (SCP) | K12: 30 | L12: 0 | M12: 30 | N12: Активен | P12: Супер МТС. Область (МАСС) (SCP) | Q12: =IF(AND(DAY(выгрузка__22[[#This Row],[Дата отправки смс]])>=1,DAY(выгрузка__22[[#This Row],[Дата отправки смс]])<=14,MONTH(выгрузка__22[[#This Row],[Дата отправки смс]])=10),1,0) -> 0 | R12: =IF(выгрузка__22[[#This Row],[Дата регистрации]]="",0,1) -> 1 | S12: =IF(ISNA(VLOOKUP(выгрузка__22[[#This Row],[ЛС дилера]],'дилеры участники'!A:A,1,0)),0,1) -> 0 | T12: =IF(ISNA(VLOOKUP(выгрузка__22[[#This Row],[ТП комплекта текущий без города (столбец создан с помощью Power Query)]],Таблица3[Название ТП комплекта],1,0)),0,1) -> 1 | U12: =IF(ISNA(IF(выгрузка__22[[#This Row],[Канал продажи]]="Непрофильный",VLOOKUP(выгрузка__22[[#This Row],[ТП комплекта текущий без города (столбец создан с помощью Power Query)]],Таблица3[[Название ТП комплекта]:[Непрофильный]],3,0),VLOOKUP(выгрузка__22[[#This Row],[ТП комплекта текущий без города (столбец создан с помощью Power Query)]],Таблица3[[Название ТП комплекта]:[Непрофильный]],2,0)))=FALSE,1,0) -> 1 | V12: =IF(T12=1,IF(выгрузка__22[[#This Row],[Сумма дополнительного платежа и стартового баланса]]>300,VLOOKUP(выгрузка__22[[#This Row],[ТП комплекта текущий без города (столбец создан с помощью Power Query)]],Таблица3[],6,0),IF(выгрузка__22[[#This Row],[Сумма дополнительного платежа и стартового баланса]]>200,VLOOKUP(выгрузка__22[[#This Row],[ТП комплекта текущий без города (столбец создан с помощью Power Query)]],Таблица3[],5,0),IF(выгрузка__22[[#This Row],[Сумма дополнительного платежа и стартового баланса]]>100,VLOOKUP(выгрузка__22[[#This Row],[ТП комплекта текущий без города (столбец создан с помощью Power Query)]],Таблица3[],4,0),0))),0) -> 0 | W12: Супер МТС. Область | X12: =IF(выгрузка__22[[#This Row],[Дата активации]]<>0,IF(выгрузка__22[[#This Row],[Дата блокировки]]<>"",CEILING((выгрузка__22[[#This Row],[Дата блокировки]]-выгрузка__22[[#This Row],[Дата активации]])/30,1),0),0) -> 0 | Y12: =IF(выгрузка__22[[#This Row],[Дата блокировки]]<>"",1,0) -> 0
A13: 41593.501 | B13: 985210 | C13: 8542892 | D13: 41589.767 | E13: =IF(выгрузка__22[[#This Row],[Дата активации]]<>"",MONTH(выгрузка__22[[#This Row],[Дата активации]]),0) -> 11 | F13: 41591.805 | G13: 64626 | H13: Непрофильный | I13: Тверь | J13: - МТС Коннект-4 (МАСС) (SCP) | K13: 401 | L13: 0 | M13: 401 | N13: Активен | P13: МТС Коннект-4 (МАСС) (SCP) | Q13: =IF(AND(DAY(выгрузка__22[[#This Row],[Дата отправки смс]])>=1,DAY(выгрузка__22[[#This Row],[Дата отправки смс]])<=14,MONTH(выгрузка__22[[#This Row],[Дата отправки смс]])=10),1,0) -> 0 | R13: =IF(выгрузка__22[[#This Row],[Дата регистрации]]="",0,1) -> 1 | S13: =IF(ISNA(VLOOKUP(выгрузка__22[[#This Row],[ЛС дилера]],'дилеры участники'!A:A,1,0)),0,1) -> 0 | T13: =IF(ISNA(VLOOKUP(выгрузка__22[[#This Row],[ТП комплекта текущий без города (столбец создан с помощью Power Query)]],Таблица3[Название ТП комплекта],1,0)),0,1) -> 1 | U13: =IF(ISNA(IF(выгрузка__22[[#This Row],[Канал продажи]]="Непрофильный",VLOOKUP(выгрузка__22[[#This Row],[ТП комплекта текущий без города (столбец создан с помощью Power Query)]],Таблица3[[Название ТП комплекта]:[Непрофильный]],3,0),VLOOKUP(выгрузка__22[[#This Row],[ТП комплекта текущий без города (столбец создан с помощью Power Query)]],Таблица3[[Название ТП комплекта]:[Непрофильный]],2,0)))=FALSE,1,0) -> 1 | V13: =IF(T13=1,IF(выгрузка__22[[#This Row],[Сумма дополнительного платежа и стартового баланса]]>300,VLOOKUP(выгрузка__22[[#This Row],[ТП комплекта текущий без города (столбец создан с помощью Power Query)]],Таблица3[],6,0),IF(выгрузка__22[[#This Row],[Сумма дополнительного платежа и стартового баланса]]>200,VLOOKUP(выгрузка__22[[#This Row],[ТП комплекта текущий без города (столбец создан с помощью Power Query)]],Таблица3[],5,0),IF(выгрузка__22[[#This Row],[Сумма дополнительного платежа и стартового баланса]]>100,VLOOKUP(выгрузка__22[[#This Row],[ТП комплекта текущий без города (столбец создан с помощью Power Query)]],Таблица3[],4,0),0))),0) -> 170 | W13: МТС Коннект-4 | X13: =IF(выгрузка__22[[#This Row],[Дата активации]]<>0,IF(выгрузка__22[[#This Row],[Дата блокировки]]<>"",CEILING((выгрузка__22[[#This Row],[Дата блокировки]]-выгрузка__22[[#This Row],[Дата активации]])/30,1),0),0) -> 0 | Y13: =IF(выгрузка__22[[#This Row],[Дата блокировки]]<>"",1,0) -> 0
A14: 41593.599 | B14: 916888 | C14: 1751205 | D14: 41589.757 | E14: =IF(выгрузка__22[[#This Row],[Дата активации]]<>"",MONTH(выгрузка__22[[#This Row],[Дата активации]]),0) -> 11 | F14: 41591.876 | G14: 64626 | H14: Непрофильный | I14: Тверь | J14: - Супер МТС. Область (МАСС) (SCP) | K14: 30 | L14: 0 | M14: 30 | N14: Активен | P14: Супер МТС. Область (МАСС) (SCP) | Q14: =IF(AND(DAY(выгрузка__22[[#This Row],[Дата отправки смс]])>=1,DAY(выгрузка__22[[#This Row],[Дата отправки смс]])<=14,MONTH(выгрузка__22[[#This Row],[Дата отправки смс]])=10),1,0) -> 0 | R14: =IF(выгрузка__22[[#This Row],[Дата регистрации]]="",0,1) -> 1 | S14: =IF(ISNA(VLOOKUP(выгрузка__22[[#This Row],[ЛС дилера]],'дилеры участники'!A:A,1,0)),0,1) -> 0 | T14: =IF(ISNA(VLOOKUP(выгрузка__22[[#This Row],[ТП комплекта текущий без города (столбец создан с помощью Power Query)]],Таблица3[Название ТП комплекта],1,0)),0,1) -> 1 | U14: =IF(ISNA(IF(выгрузка__22[[#This Row],[Канал продажи]]="Непрофильный",VLOOKUP(выгрузка__22[[#This Row],[ТП комплекта текущий без города (столбец создан с помощью Power Query)]],Таблица3[[Название ТП комплекта]:[Непрофильный]],3,0),VLOOKUP(выгрузка__22[[#This Row],[ТП комплекта текущий без города (столбец создан с помощью Power Query)]],Таблица3[[Название ТП комплекта]:[Непрофильный]],2,0)))=FALSE,1,0) -> 1 | V14: =IF(T14=1,IF(выгрузка__22[[#This Row],[Сумма дополнительного платежа и стартового баланса]]>300,VLOOKUP(выгрузка__22[[#This Row],[ТП комплекта текущий без города (столбец создан с помощью Power Query)]],Таблица3[],6,0),IF(выгрузка__22[[#This Row],[Сумма дополнительного платежа и стартового баланса]]>200,VLOOKUP(выгрузка__22[[#This Row],[ТП комплекта текущий без города (столбец создан с помощью Power Query)]],Таблица3[],5,0),IF(выгрузка__22[[#This Row],[Сумма дополнительного платежа и стартового баланса]]>100,VLOOKUP(выгрузка__22[[#This Row],[ТП комплекта текущий без города (столбец создан с помощью Power Query)]],Таблица3[],4,0),0))),0) -> 0 | W14: Супер МТС. Область | X14: =IF(выгрузка__22[[#This Row],[Дата активации]]<>0,IF(выгрузка__22[[#This Row],[Дата блокировки]]<>"",CEILING((выгрузка__22[[#This Row],[Дата блокировки]]-выгрузка__22[[#This Row],[Дата активации]])/30,1),0),0) -> 0 | Y14: =IF(выгрузка__22[[#This Row],[Дата блокировки]]<>"",1,0) -> 0
A15: 41593.598 | B15: 916888 | C15: 1698728 | D15: 41589.744 | E15: =IF(выгрузка__22[[#This Row],[Дата активации]]<>"",MONTH(выгрузка__22[[#This Row],[Дата активации]]),0) -> 11 | F15: 41591.94 | G15: 64626 | H15: Непрофильный | I15: Тверь | J15: - Супер МТС. Область (МАСС) (SCP) | K15: 30 | L15: 0 | M15: 30 | N15: Активен | P15: Супер МТС. Область (МАСС) (SCP) | Q15: =IF(AND(DAY(выгрузка__22[[#This Row],[Дата отправки смс]])>=1,DAY(выгрузка__22[[#This Row],[Дата отправки смс]])<=14,MONTH(выгрузка__22[[#This Row],[Дата отправки смс]])=10),1,0) -> 0 | R15: =IF(выгрузка__22[[#This Row],[Дата регистрации]]="",0,1) -> 1 | S15: =IF(ISNA(VLOOKUP(выгрузка__22[[#This Row],[ЛС дилера]],'дилеры участники'!A:A,1,0)),0,1) -> 0 | T15: =IF(ISNA(VLOOKUP(выгрузка__22[[#This Row],[ТП комплекта текущий без города (столбец создан с помощью Power Query)]],Таблица3[Название ТП комплекта],1,0)),0,1) -> 1 | U15: =IF(ISNA(IF(выгрузка__22[[#This Row],[Канал продажи]]="Непрофильный",VLOOKUP(выгрузка__22[[#This Row],[ТП комплекта текущий без города (столбец создан с помощью Power Query)]],Таблица3[[Название ТП комплекта]:[Непрофильный]],3,0),VLOOKUP(выгрузка__22[[#This Row],[ТП комплекта текущий без города (столбец создан с помощью Power Query)]],Таблица3[[Название ТП комплекта]:[Непрофильный]],2,0)))=FALSE,1,0) -> 1 | V15: =IF(T15=1,IF(выгрузка__22[[#This Row],[Сумма дополнительного платежа и стартового баланса]]>300,VLOOKUP(выгрузка__22[[#This Row],[ТП комплекта текущий без города (столбец создан с помощью Power Query)]],Таблица3[],6,0),IF(выгрузка__22[[#This Row],[Сумма дополнительного платежа и стартового баланса]]>200,VLOOKUP(выгрузка__22[[#This Row],[ТП комплекта текущий без города (столбец создан с помощью Power Query)]],Таблица3[],5,0),IF(выгрузка__22[[#This Row],[Сумма дополнительного платежа и стартового баланса]]>100,VLOOKUP(выгрузка__22[[#This Row],[ТП комплекта текущий без города (столбец создан с помощью Power Query)]],Таблица3[],4,0),0))),0) -> 0 | W15: Супер МТС. Область | X15: =IF(выгрузка__22[[#This Row],[Дата активации]]<>0,IF(выгрузка__22[[#This Row],[Дата блокировки]]<>"",CEILING((выгрузка__22[[#This Row],[Дата блокировки]]-выгрузка__22[[#This Row],[Дата активации]])/30,1),0),0) -> 0 | Y15: =IF(выгрузка__22[[#This Row],[Дата блокировки]]<>"",1,0) -> 0
A16: 41593.567 | B16: 916513 | C16: 1698739 | D16: 41589.545 | E16: =IF(выгрузка__22[[#This Row],[Дата активации]]<>"",MONTH(выгрузка__22[[#This Row],[Дата активации]]),0) -> 11 | F16: 41591.987 | G16: 64626 | H16: Непрофильный | I16: Тверь | J16: - Супер МТС (МАСС) (SCP) | K16: 1 | L16: 0 | M16: 1 | N16: Активен | P16: Супер МТС (МАСС) (SCP) | Q16: =IF(AND(DAY(выгрузка__22[[#This Row],[Дата отправки смс]])>=1,DAY(выгрузка__22[[#This Row],[Дата отправки смс]])<=14,MONTH(выгрузка__22[[#This Row],[Дата отправки смс]])=10),1,0) -> 0 | R16: =IF(выгрузка__22[[#This Row],[Дата регистрации]]="",0,1) -> 1 | S16: =IF(ISNA(VLOOKUP(выгрузка__22[[#This Row],[ЛС дилера]],'дилеры участники'!A:A,1,0)),0,1) -> 0 | T16: =IF(ISNA(VLOOKUP(выгрузка__22[[#This Row],[ТП комплекта текущий без города (столбец создан с помощью Power Query)]],Таблица3[Название ТП комплекта],1,0)),0,1) -> 1 | U16: =IF(ISNA(IF(выгрузка__22[[#This Row],[Канал продажи]]="Непрофильный",VLOOKUP(выгрузка__22[[#This Row],[ТП комплекта текущий без города (столбец создан с помощью Power Query)]],Таблица3[[Название ТП комплекта]:[Непрофильный]],3,0),VLOOKUP(выгрузка__22[[#This Row],[ТП комплекта текущий без города (столбец создан с помощью Power Query)]],Таблица3[[Название ТП комплекта]:[Непрофильный]],2,0)))=FALSE,1,0) -> 1 | V16: =IF(T16=1,IF(выгрузка__22[[#This Row],[Сумма дополнительного платежа и стартового баланса]]>300,VLOOKUP(выгрузка__22[[#This Row],[ТП комплекта текущий без города (столбец создан с помощью Power Query)]],Таблица3[],6,0),IF(выгрузка__22[[#This Row],[Сумма дополнительного платежа и стартового баланса]]>200,VLOOKUP(выгрузка__22[[#This Row],[ТП комплекта текущий без города (столбец создан с помощью Power Query)]],Таблица3[],5,0),IF(выгрузка__22[[#This Row],[Сумма дополнительного платежа и стартового баланса]]>100,VLOOKUP(выгрузка__22[[#This Row],[ТП комплекта текущий без города (столбец создан с помощью Power Query)]],Таблица3[],4,0),0))),0) -> 0 | W16: Супер МТС | X16: =IF(выгрузка__22[[#This Row],[Дата активации]]<>0,IF(выгрузка__22[[#This Row],[Дата блокировки]]<>"",CEILING((выгрузка__22[[#This Row],[Дата блокировки]]-выгрузка__22[[#This Row],[Дата активации]])/30,1),0),0) -> 0 | Y16: =IF(выгрузка__22[[#This Row],[Дата блокировки]]<>"",1,0) -> 0
A17: 41593.925 | B17: 916531 | C17: 1754677 | D17: 41589.319 | E17: =IF(выгрузка__22[[#This Row],[Дата активации]]<>"",MONTH(выгрузка__22[[#This Row],[Дата активации]]),0) -> 11 | G17: 64628 | H17: Непрофильный | I17: Тверь | J17: - Smart mini (МАСС) (SCP) | K17: 1 | L17: 200 | M17: 201 | N17: Активен | P17: Smart mini (МАСС) (SCP) | Q17: =IF(AND(DAY(выгрузка__22[[#This Row],[Дата отправки смс]])>=1,DAY(выгрузка__22[[#This Row],[Дата отправки смс]])<=14,MONTH(выгрузка__22[[#This Row],[Дата отправки смс]])=10),1,0) -> 0 | R17: =IF(выгрузка__22[[#This Row],[Дата регистрации]]="",0,1) -> 0 | S17: =IF(ISNA(VLOOKUP(выгрузка__22[[#This Row],[ЛС дилера]],'дилеры участники'!A:A,1,0)),0,1) -> 0 | T17: =IF(ISNA(VLOOKUP(выгрузка__22[[#This Row],[ТП комплекта текущий без города (столбец создан с помощью Power Query)]],Таблица3[Название ТП комплекта],1,0)),0,1) -> 1 | U17: =IF(ISNA(IF(выгрузка__22[[#This Row],[Канал продажи]]="Непрофильный",VLOOKUP(выгрузка__22[[#This Row],[ТП комплекта текущий без города (столбец создан с помощью Power Query)]],Таблица3[[Название ТП комплекта]:[Непрофильный]],3,0),VLOOKUP(выгрузка__22[[#This Row],[ТП комплекта текущий без города (столбец создан с помощью Power Query)]],Таблица3[[Название ТП комплекта]:[Непрофильный]],2,0)))=FALSE,1,0) -> 1 | V17: =IF(T17=1,IF(выгрузка__22[[#This Row],[Сумма дополнительного платежа и стартового баланса]]>300,VLOOKUP(выгрузка__22[[#This Row],[ТП комплекта текущий без города (столбец создан с помощью Power Query)]],Таблица3[],6,0),IF(выгрузка__22[[#This Row],[Сумма дополнительного платежа и стартового баланса]]>200,VLOOKUP(выгрузка__22[[#This Row],[ТП комплекта текущий без города (столбец создан с помощью Power Query)]],Таблица3[],5,0),IF(выгрузка__22[[#This Row],[Сумма дополнительного платежа и стартового баланса]]>100,VLOOKUP(выгрузка__22[[#This Row],[ТП комплекта текущий без города (столбец создан с помощью Power Query)]],Таблица3[],4,0),0))),0) -> 110 | W17: Smart mini | X17: =IF(выгрузка__22[[#This Row],[Дата активации]]<>0,IF(выгрузка__22[[#This Row],[Дата блокировки]]<>"",CEILING((выгрузка__22[[#This Row],[Дата блокировки]]-выгрузка__22[[#This Row],[Дата активации]])/30,1),0),0) -> 0 | Y17: =IF(выгрузка__22[[#This Row],[Дата блокировки]]<>"",1,0) -> 0
A18: 41593.591 | B18: 916512 | C18: 1698590 | D18: 41588.993 | E18: =IF(выгрузка__22[[#This Row],[Дата активации]]<>"",MONTH(выгрузка__22[[#This Row],[Дата активации]]),0) -> 11 | F18: 41591.939 | G18: 64626 | H18: Непрофильный | I18: Тверь | J18: - Супер МТС. Область (МАСС) (SCP) | K18: 30 | L18: 0 | M18: 30 | N18: Активен | P18: Супер МТС. Область (МАСС) (SCP) | Q18: =IF(AND(DAY(выгрузка__22[[#This Row],[Дата отправки смс]])>=1,DAY(выгрузка__22[[#This Row],[Дата отправки смс]])<=14,MONTH(выгрузка__22[[#This Row],[Дата отправки смс]])=10),1,0) -> 0 | R18: =IF(выгрузка__22[[#This Row],[Дата регистрации]]="",0,1) -> 1 | S18: =IF(ISNA(VLOOKUP(выгрузка__22[[#This Row],[ЛС дилера]],'дилеры участники'!A:A,1,0)),0,1) -> 0 | T18: =IF(ISNA(VLOOKUP(выгрузка__22[[#This Row],[ТП комплекта текущий без города (столбец создан с помощью Power Query)]],Таблица3[Название ТП комплекта],1,0)),0,1) -> 1 | U18: =IF(ISNA(IF(выгрузка__22[[#This Row],[Канал продажи]]="Непрофильный",VLOOKUP(выгрузка__22[[#This Row],[ТП комплекта текущий без города (столбец создан с помощью Power Query)]],Таблица3[[Название ТП комплекта]:[Непрофильный]],3,0),VLOOKUP(выгрузка__22[[#This Row],[ТП комплекта текущий без города (столбец создан с помощью Power Query)]],Таблица3[[Название ТП комплекта]:[Непрофильный]],2,0)))=FALSE,1,0) -> 1 | V18: =IF(T18=1,IF(выгрузка__22[[#This Row],[Сумма дополнительного платежа и стартового баланса]]>300,VLOOKUP(выгрузка__22[[#This Row],[ТП комплекта текущий без города (столбец создан с помощью Power Query)]],Таблица3[],6,0),IF(выгрузка__22[[#This Row],[Сумма дополнительного платежа и стартового баланса]]>200,VLOOKUP(выгрузка__22[[#This Row],[ТП комплекта текущий без города (столбец создан с помощью Power Query)]],Таблица3[],5,0),IF(выгрузка__22[[#This Row],[Сумма дополнительного платежа и стартового баланса]]>100,VLOOKUP(выгрузка__22[[#This Row],[ТП комплекта текущий без города (столбец создан с помощью Power Query)]],Таблица3[],4,0),0))),0) -> 0 | W18: Супер МТС. Область | X18: =IF(выгрузка__22[[#This Row],[Дата активации]]<>0,IF(выгрузка__22[[#This Row],[Дата блокировки]]<>"",CEILING((выгрузка__22[[#This Row],[Дата блокировки]]-выгрузка__22[[#This Row],[Дата активации]])/30,1),0),0) -> 0 | Y18: =IF(выгрузка__22[[#This Row],[Дата блокировки]]<>"",1,0) -> 0
A19: 41593.596 | B19: 916888 | C19: 1698667 | D19: 41588.898 | E19: =IF(выгрузка__22[[#This Row],[Дата активации]]<>"",MONTH(выгрузка__22[[#This Row],[Дата активации]]),0) -> 11 | F19: 41591.939 | G19: 64626 | H19: Непрофильный | I19: Тверь | J19: - Супер МТС. Область (МАСС) (SCP) | K19: 30 | L19: 0 | M19: 30 | N19: Активен | P19: Супер МТС. Область (МАСС) (SCP) | Q19: =IF(AND(DAY(выгрузка__22[[#This Row],[Дата отправки смс]])>=1,DAY(выгрузка__22[[#This Row],[Дата отправки смс]])<=14,MONTH(выгрузка__22[[#This Row],[Дата отправки смс]])=10),1,0) -> 0 | R19: =IF(выгрузка__22[[#This Row],[Дата регистрации]]="",0,1) -> 1 | S19: =IF(ISNA(VLOOKUP(выгрузка__22[[#This Row],[ЛС дилера]],'дилеры участники'!A:A,1,0)),0,1) -> 0 | T19: =IF(ISNA(VLOOKUP(выгрузка__22[[#This Row],[ТП комплекта текущий без города (столбец создан с помощью Power Query)]],Таблица3[Название ТП комплекта],1,0)),0,1) -> 1 | U19: =IF(ISNA(IF(выгрузка__22[[#This Row],[Канал продажи]]="Непрофильный",VLOOKUP(выгрузка__22[[#This Row],[ТП комплекта текущий без города (столбец создан с помощью Power Query)]],Таблица3[[Название ТП комплекта]:[Непрофильный]],3,0),VLOOKUP(выгрузка__22[[#This Row],[ТП комплекта текущий без города (столбец создан с помощью Power Query)]],Таблица3[[Название ТП комплекта]:[Непрофильный]],2,0)))=FALSE,1,0) -> 1 | V19: =IF(T19=1,IF(выгрузка__22[[#This Row],[Сумма дополнительного платежа и стартового баланса]]>300,VLOOKUP(выгрузка__22[[#This Row],[ТП комплекта текущий без города (столбец создан с помощью Power Query)]],Таблица3[],6,0),IF(выгрузка__22[[#This Row],[Сумма дополнительного платежа и стартового баланса]]>200,VLOOKUP(выгрузка__22[[#This Row],[ТП комплекта текущий без города (столбец создан с помощью Power Query)]],Таблица3[],5,0),IF(выгрузка__22[[#This Row],[Сумма дополнительного платежа и стартового баланса]]>100,VLOOKUP(выгрузка__22[[#This Row],[ТП комплекта текущий без города (столбец создан с помощью Power Query)]],Таблица3[],4,0),0))),0) -> 0 | W19: Супер МТС. Область | X19: =IF(выгрузка__22[[#This Row],[Дата активации]]<>0,IF(выгрузка__22[[#This Row],[Дата блокировки]]<>"",CEILING((выгрузка__22[[#This Row],[Дата блокировки]]-выгрузка__22[[#This Row],[Дата активации]])/30,1),0),0) -> 0 | Y19: =IF(выгрузка__22[[#This Row],[Дата блокировки]]<>"",1,0) -> 0
A20: 41588.724 | B20: 919100 | C20: 8528599 | D20: 41588.868 | E20: =IF(выгрузка__22[[#This Row],[Дата активации]]<>"",MONTH(выгрузка__22[[#This Row],[Дата активации]]),0) -> 11 | G20: 79956 | H20: Непрофильный | I20: Тверь | J20: - Супер МТС (МАСС) (SCP) | K20: 30 | L20: 0 | M20: 30 | N20: Активен | P20: Супер МТС (МАСС) (SCP) | Q20: =IF(AND(DAY(выгрузка__22[[#This Row],[Дата отправки смс]])>=1,DAY(выгрузка__22[[#This Row],[Дата отправки смс]])<=14,MONTH(выгрузка__22[[#This Row],[Дата отправки смс]])=10),1,0) -> 0 | R20: =IF(выгрузка__22[[#This Row],[Дата регистрации]]="",0,1) -> 0 | S20: =IF(ISNA(VLOOKUP(выгрузка__22[[#This Row],[ЛС дилера]],'дилеры участники'!A:A,1,0)),0,1) -> 1 | T20: =IF(ISNA(VLOOKUP(выгрузка__22[[#This Row],[ТП комплекта текущий без города (столбец создан с помощью Power Query)]],Таблица3[Название ТП комплекта],1,0)),0,1) -> 1 | U20: =IF(ISNA(IF(выгрузка__22[[#This Row],[Канал продажи]]="Непрофильный",VLOOKUP(выгрузка__22[[#This Row],[ТП комплекта текущий без города (столбец создан с помощью Power Query)]],Таблица3[[Название ТП комплекта]:[Непрофильный]],3,0),VLOOKUP(выгрузка__22[[#This Row],[ТП комплекта текущий без города (столбец создан с помощью Power Query)]],Таблица3[[Название ТП комплекта]:[Непрофильный]],2,0)))=FALSE,1,0) -> 1 | V20: =IF(T20=1,IF(выгрузка__22[[#This Row],[Сумма дополнительного платежа и стартового баланса]]>300,VLOOKUP(выгрузка__22[[#This Row],[ТП комплекта текущий без города (столбец создан с помощью Power Query)]],Таблица3[],6,0),IF(выгрузка__22[[#This Row],[Сумма дополнительного платежа и стартового баланса]]>200,VLOOKUP(выгрузка__22[[#This Row],[ТП комплекта текущий без города (столбец создан с помощью Power Query)]],Таблица3[],5,0),IF(выгрузка__22[[#This Row],[Сумма дополнительного платежа и стартового баланса]]>100,VLOOKUP(выгрузка__22[[#This Row],[ТП комплекта текущий без города (столбец создан с помощью Power Query)]],Таблица3[],4,0),0))),0) -> 0 | W20: Супер МТС | X20: =IF(выгрузка__22[[#This Row],[Дата активации]]<>0,IF(выгрузка__22[[#This Row],[Дата блокировки]]<>"",CEILING((выгрузка__22[[#This Row],[Дата блокировки]]-выгрузка__22[[#This Row],[Дата активации]])/30,1),0),0) -> 0 | Y20: =IF(выгрузка__22[[#This Row],[Дата блокировки]]<>"",1,0) -> 0
